<?xml version="1.0" encoding="UTF-8"?>
<!-- Generated by org.testng.reporters.JUnitReportReporter -->
<testsuite hostname="cpj" name="com.yiibai.primera.testng.cases.LoginTest" tests="5" failures="0" timestamp="30 Aug 2017 09:22:31 GMT" time="57.035" errors="1">
  <testcase name="loginChinese" time="4.515" classname="com.yiibai.primera.testng.cases.LoginTest"/>
  <testcase name="loginEmpty" time="4.218" classname="com.yiibai.primera.testng.cases.LoginTest"/>
  <testcase name="loginErrorUser" time="39.372" classname="com.yiibai.primera.testng.cases.LoginTest"/>
  <testcase name="loginErrorNum" time="4.276" classname="com.yiibai.primera.testng.cases.LoginTest"/>
  <testcase name="loginConfim" time="4.654" classname="com.yiibai.primera.testng.cases.LoginTest">
    <error type="java.lang.AssertionError" message="帐号密码对的情况登录 expected [true] but found [false]">
      <![CDATA[java.lang.AssertionError: 帐号密码对的情况登录 expected [true] but found [false]
	at org.testng.Assert.fail(Assert.java:94)
	at org.testng.Assert.failNotEquals(Assert.java:494)
	at org.testng.Assert.assertTrue(Assert.java:42)
	at com.yiibai.primera.testng.cases.LoginTest.loginConfim(LoginTest.java:76)
	at sun.reflect.NativeMethodAccessorImpl.invoke0(Native Method)
	at sun.reflect.NativeMethodAccessorImpl.invoke(NativeMethodAccessorImpl.java:62)
	at sun.reflect.DelegatingMethodAccessorImpl.invoke(DelegatingMethodAccessorImpl.java:43)
	at java.lang.reflect.Method.invoke(Method.java:497)
	at org.testng.internal.MethodInvocationHelper.invokeMethod(MethodInvocationHelper.java:84)
	at org.testng.internal.Invoker.invokeMethod(Invoker.java:714)
	at org.testng.internal.Invoker.invokeTestMethod(Invoker.java:901)
	at org.testng.internal.Invoker.invokeTestMethods(Invoker.java:1231)
	at org.testng.internal.TestMethodWorker.invokeTestMethods(TestMethodWorker.java:127)
	at org.testng.internal.TestMethodWorker.run(TestMethodWorker.java:111)
	at org.testng.TestRunner.privateRun(TestRunner.java:767)
	at org.testng.TestRunner.run(TestRunner.java:617)
	at org.testng.SuiteRunner.runTest(SuiteRunner.java:334)
	at org.testng.SuiteRunner.runSequentially(SuiteRunner.java:329)
	at org.testng.SuiteRunner.privateRun(SuiteRunner.java:291)
	at org.testng.SuiteRunner.run(SuiteRunner.java:240)
	at org.testng.SuiteRunnerWorker.runSuite(SuiteRunnerWorker.java:52)
	at org.testng.SuiteRunnerWorker.run(SuiteRunnerWorker.java:86)
	at org.testng.TestNG.runSuitesSequentially(TestNG.java:1224)
	at org.testng.TestNG.runSuitesLocally(TestNG.java:1149)
	at org.testng.TestNG.run(TestNG.java:1057)
	at org.testng.remote.AbstractRemoteTestNG.run(AbstractRemoteTestNG.java:132)
	at org.testng.remote.RemoteTestNG.initAndRun(RemoteTestNG.java:230)
	at org.testng.remote.RemoteTestNG.main(RemoteTestNG.java:76)
]]>
    </error>
  </testcase> <!-- loginConfim -->
</testsuite> <!-- com.yiibai.primera.testng.cases.LoginTest -->
